Workbook

Sheet Budget - Topeka
B1: Topeka Self Storage
B2: Budget
B3: January - December 2026
B5: 46023 | C5: 46054 | D5: 46082 | E5: 46113 | F5: 46143 | G5: 46174 | H5: 46204 | I5: 46235 | J5: 46266 | K5: 46296 | L5: 46327 | M5: 46357
A6: Rented | B6: ='Budget - Grantville'!B6+'Budget - Tyler'!B6 -> 8 | C6: ='Budget - Grantville'!C6+'Budget - Tyler'!C6 -> 11 | D6: ='Budget - Grantville'!D6+'Budget - Tyler'!D6 -> 11 | E6: ='Budget - Grantville'!E6+'Budget - Tyler'!E6 -> 13 | F6: ='Budget - Grantville'!F6+'Budget - Tyler'!F6 -> 15 | G6: ='Budget - Grantville'!G6+'Budget - Tyler'!G6 -> 15 | H6: ='Budget - Grantville'!H6+'Budget - Tyler'!H6 -> 18 | I6: ='Budget - Grantville'!I6+'Budget - Tyler'!I6 -> 18 | ... M6: ='Budget - Grantville'!M6+'Budget - Tyler'!M6 -> 12
A7: Vacated | B7: ='Budget - Grantville'!B7+'Budget - Tyler'!B7 -> 10.56 | C7: ='Budget - Grantville'!C7+'Budget - Tyler'!C7 -> 12.32 | D7: ='Budget - Grantville'!D7+'Budget - Tyler'!D7 -> 12.2276 | E7: ='Budget - Grantville'!E7+'Budget - Tyler'!E7 -> 12.141668 | F7: ='Budget - Grantville'!F7+'Budget - Tyler'!F7 -> 12.201751 | G7: ='Budget - Grantville'!G7+'Budget - Tyler'!G7 -> 12.397629 | H7: ='Budget - Grantville'!H7+'Budget - Tyler'!H7 -> 12.579795 | I7: ='Budget - Grantville'!I7+'Budget - Tyler'!I7 -> 12.959209 | ... M7: ='Budget - Grantville'!M7+'Budget - Tyler'!M7 -> 11.927499
A8: Net occupied | B8: ='Budget - Grantville'!B8+'Budget - Tyler'!B8 -> 176 | C8: ='Budget - Grantville'!C8+'Budget - Tyler'!C8 -> 174.68 | D8: ='Budget - Grantville'!D8+'Budget - Tyler'!D8 -> 173.4524 | E8: ='Budget - Grantville'!E8+'Budget - Tyler'!E8 -> 174.31073 | F8: ='Budget - Grantville'!F8+'Budget - Tyler'!F8 -> 177.10898 | G8: ='Budget - Grantville'!G8+'Budget - Tyler'!G8 -> 179.71135 | H8: ='Budget - Grantville'!H8+'Budget - Tyler'!H8 -> 185.13156 | I8: ='Budget - Grantville'!I8+'Budget - Tyler'!I8 -> 190.17235 | ... M8: ='Budget - Grantville'!M8+'Budget - Tyler'!M8 -> 186.57776
A9: % occupied | B9: =B8/(126+82) -> 0.84615385 | C9: =C8/(126+82) -> 0.83980769 | D9: =D8/(126+82) -> 0.83390577 | E9: =E8/(126+82) -> 0.83803237 | F9: =F8/(126+82) -> 0.85148548 | G9: =G8/(126+82) -> 0.86399689 | H9: =H8/(126+82) -> 0.89005556 | I9: =I8/(126+82) -> 0.91429014 | ... M9: =M8/(126+82) -> 0.89700846 | O9: T12 Actual
B10: 46023 | C10: 46054 | D10: 46082 | E10: 46113 | F10: 46143 | G10: 46174 | H10: 46204 | I10: 46235 | J10: 46266 | K10: 46296 | L10: 46327 | M10: 46357 | N10: Total | O10: 10/1/2024 - 9/30/2025
A11: Revenue Projection
A12: Rent Income | B12: ='Budget - Grantville'!B12+'Budget - Tyler'!B12 -> 24737.009 | C12: ='Budget - Grantville'!C12+'Budget - Tyler'!C12 -> 24623.314 | D12: ='Budget - Grantville'!D12+'Budget - Tyler'!D12 -> 24517.577 | E12: ='Budget - Grantville'!E12+'Budget - Tyler'!E12 -> 24640.72 | F12: ='Budget - Grantville'!F12+'Budget - Tyler'!F12 -> 25076.663 | G12: ='Budget - Grantville'!G12+'Budget - Tyler'!G12 -> 25482.09 | H12: ='Budget - Grantville'!H12+'Budget - Tyler'!H12 -> 26191.355 | I12: ='Budget - Grantville'!I12+'Budget - Tyler'!I12 -> 26850.972 | ... M12: ='Budget - Grantville'!M12+'Budget - Tyler'!M12 -> 26309.128 | N12: =SUM(B12:M12) -> 307831.59 | O12: =222505.71+46989.65-483.03 -> 269012.33
A13: Other Rent Income | N13: =SUM(B13:M13) -> 0 | O13: =SUM(C13:N13) -> 0
A14: Other Rent Income | N14: =SUM(B14:M14) -> 0 | O14: =SUM(C14:N14) -> 0
A15: Total Rental Income | B15: =SUM(B12:B14) -> 24737.009 | C15: =SUM(C12:C14) -> 24623.314 | D15: =SUM(D12:D14) -> 24517.577 | E15: =SUM(E12:E14) -> 24640.72 | F15: =SUM(F12:F14) -> 25076.663 | G15: =SUM(G12:G14) -> 25482.09 | H15: =SUM(H12:H14) -> 26191.355 | I15: =SUM(I12:I14) -> 26850.972 | ... M15: =SUM(M12:M14) -> 26309.128 | N15: =(((((((((((B15)+(C15))+(D15))+(E15))+(F15))+(G15))+(H15))+(I15))+(J15))+(K15))+(L15))+(M15) -> 307831.59 | O15: =SUM(O12:O14) -> 269012.33
A16: Fee Income
A17: Admin Fees | B17: ='Budget - Grantville'!B17+'Budget - Tyler'!B17 -> 160 | C17: ='Budget - Grantville'!C17+'Budget - Tyler'!C17 -> 220 | D17: ='Budget - Grantville'!D17+'Budget - Tyler'!D17 -> 220 | E17: ='Budget - Grantville'!E17+'Budget - Tyler'!E17 -> 260 | F17: ='Budget - Grantville'!F17+'Budget - Tyler'!F17 -> 300 | G17: ='Budget - Grantville'!G17+'Budget - Tyler'!G17 -> 300 | H17: ='Budget - Grantville'!H17+'Budget - Tyler'!H17 -> 360 | I17: ='Budget - Grantville'!I17+'Budget - Tyler'!I17 -> 360 | ... M17: ='Budget - Grantville'!M17+'Budget - Tyler'!M17 -> 240 | N17: =SUM(B17:M17) -> 3140 | O17: 4175.54
A18: Late Fee Income | B18: ='Budget - Grantville'!B18+'Budget - Tyler'!B18 -> 742.11027 | C18: ='Budget - Grantville'!C18+'Budget - Tyler'!C18 -> 738.69941 | D18: ='Budget - Grantville'!D18+'Budget - Tyler'!D18 -> 735.5273 | E18: ='Budget - Grantville'!E18+'Budget - Tyler'!E18 -> 739.22162 | F18: ='Budget - Grantville'!F18+'Budget - Tyler'!F18 -> 752.2999 | G18: ='Budget - Grantville'!G18+'Budget - Tyler'!G18 -> 764.4627 | H18: ='Budget - Grantville'!H18+'Budget - Tyler'!H18 -> 785.74066 | I18: ='Budget - Grantville'!I18+'Budget - Tyler'!I18 -> 805.52917 | ... M18: ='Budget - Grantville'!M18+'Budget - Tyler'!M18 -> 789.27384 | N18: =SUM(B18:M18) -> 9234.9478 | O18: 8653
A19: Convenience Fee | B19: ='Budget - Grantville'!B19+'Budget - Tyler'!B19 -> 44 | C19: ='Budget - Grantville'!C19+'Budget - Tyler'!C19 -> 43.67 | D19: ='Budget - Grantville'!D19+'Budget - Tyler'!D19 -> 43.3631 | E19: ='Budget - Grantville'!E19+'Budget - Tyler'!E19 -> 43.577683 | F19: ='Budget - Grantville'!F19+'Budget - Tyler'!F19 -> 44.277245 | G19: ='Budget - Grantville'!G19+'Budget - Tyler'!G19 -> 44.927838 | H19: ='Budget - Grantville'!H19+'Budget - Tyler'!H19 -> 46.282889 | I19: ='Budget - Grantville'!I19+'Budget - Tyler'!I19 -> 47.543087 | ... M19: ='Budget - Grantville'!M19+'Budget - Tyler'!M19 -> 46.64444 | N19: =SUM(B19:M19) -> 545.03768 | O19: 95.84
A20: General Fee Income | B20: ='Budget - Grantville'!B20+'Budget - Tyler'!B20 -> 0 | C20: ='Budget - Grantville'!C20+'Budget - Tyler'!C20 -> 0 | D20: ='Budget - Grantville'!D20+'Budget - Tyler'!D20 -> 0 | E20: ='Budget - Grantville'!E20+'Budget - Tyler'!E20 -> 0 | F20: ='Budget - Grantville'!F20+'Budget - Tyler'!F20 -> 0 | G20: ='Budget - Grantville'!G20+'Budget - Tyler'!G20 -> 0 | H20: ='Budget - Grantville'!H20+'Budget - Tyler'!H20 -> 0 | I20: ='Budget - Grantville'!I20+'Budget - Tyler'!I20 -> 0 | ... M20: ='Budget - Grantville'!M20+'Budget - Tyler'!M20 -> 0 | N20: =SUM(B20:M20) -> 0 | O20: 843.48
A21: Other Fee | B21: ='Budget - Grantville'!B21+'Budget - Tyler'!B21 -> 0 | C21: ='Budget - Grantville'!C21+'Budget - Tyler'!C21 -> 0 | D21: ='Budget - Grantville'!D21+'Budget - Tyler'!D21 -> 0 | E21: ='Budget - Grantville'!E21+'Budget - Tyler'!E21 -> 0 | F21: ='Budget - Grantville'!F21+'Budget - Tyler'!F21 -> 0 | G21: ='Budget - Grantville'!G21+'Budget - Tyler'!G21 -> 0 | H21: ='Budget - Grantville'!H21+'Budget - Tyler'!H21 -> 0 | I21: ='Budget - Grantville'!I21+'Budget - Tyler'!I21 -> 0 | ... M21: ='Budget - Grantville'!M21+'Budget - Tyler'!M21 -> 0 | N21: =SUM(B21:M21) -> 0 | O21: =SUM(C21:N21) -> 0
A22: Total Fee Income | B22: =SUM(B17:B21) -> 946.11027 | C22: =SUM(C17:C21) -> 1002.3694 | D22: =SUM(D17:D21) -> 998.8904 | E22: =SUM(E17:E21) -> 1042.7993 | F22: =SUM(F17:F21) -> 1096.5771 | G22: =SUM(G17:G21) -> 1109.3905 | H22: =SUM(H17:H21) -> 1192.0236 | I22: =SUM(I17:I21) -> 1213.0723 | ... M22: =SUM(M17:M21) -> 1075.9183 | N22: =(((((((((((B22)+(C22))+(D22))+(E22))+(F22))+(G22))+(H22))+(I22))+(J22))+(K22))+(L22))+(M22) -> 12919.985 | O22: =SUM(O17:O21) -> 13767.86
A23: Ancillary Income
A24: Merchandise Income | B24: ='Budget - Grantville'!B24+'Budget - Tyler'!B24 -> 0 | C24: ='Budget - Grantville'!C24+'Budget - Tyler'!C24 -> 0 | D24: ='Budget - Grantville'!D24+'Budget - Tyler'!D24 -> 0 | E24: ='Budget - Grantville'!E24+'Budget - Tyler'!E24 -> 0 | F24: ='Budget - Grantville'!F24+'Budget - Tyler'!F24 -> 0 | G24: ='Budget - Grantville'!G24+'Budget - Tyler'!G24 -> 0 | H24: ='Budget - Grantville'!H24+'Budget - Tyler'!H24 -> 0 | I24: ='Budget - Grantville'!I24+'Budget - Tyler'!I24 -> 0 | ... M24: ='Budget - Grantville'!M24+'Budget - Tyler'!M24 -> 0 | N24: =SUM(B24:M24) -> 0 | O24: =SUM(C24:N24) -> 0
A25: Tenant Protection | B25: ='Budget - Grantville'!B25+'Budget - Tyler'!B25 -> 816.55 | C25: ='Budget - Grantville'!C25+'Budget - Tyler'!C25 -> 810.6415 | D25: ='Budget - Grantville'!D25+'Budget - Tyler'!D25 -> 805.1466 | E25: ='Budget - Grantville'!E25+'Budget - Tyler'!E25 -> 809.13633 | F25: ='Budget - Grantville'!F25+'Budget - Tyler'!F25 -> 822.24679 | G25: ='Budget - Grantville'!G25+'Budget - Tyler'!G25 -> 834.43951 | H25: ='Budget - Grantville'!H25+'Budget - Tyler'!H25 -> 859.42875 | I25: ='Budget - Grantville'!I25+'Budget - Tyler'!I25 -> 882.66874 | ... M25: ='Budget - Grantville'!M25+'Budget - Tyler'!M25 -> 865.88176 | N25: =SUM(B25:M25) -> 10119.014 | O25: 7232.79
A26: Truck Rentals | B26: ='Budget - Grantville'!B26+'Budget - Tyler'!B26 -> 0 | C26: ='Budget - Grantville'!C26+'Budget - Tyler'!C26 -> 0 | D26: ='Budget - Grantville'!D26+'Budget - Tyler'!D26 -> 0 | E26: ='Budget - Grantville'!E26+'Budget - Tyler'!E26 -> 0 | F26: ='Budget - Grantville'!F26+'Budget - Tyler'!F26 -> 0 | G26: ='Budget - Grantville'!G26+'Budget - Tyler'!G26 -> 0 | H26: ='Budget - Grantville'!H26+'Budget - Tyler'!H26 -> 0 | I26: ='Budget - Grantville'!I26+'Budget - Tyler'!I26 -> 0 | ... M26: ='Budget - Grantville'!M26+'Budget - Tyler'!M26 -> 0 | N26: =SUM(B26:M26) -> 0 | O26: =SUM(C26:N26) -> 0
A27: Propane Sales | B27: ='Budget - Grantville'!B27+'Budget - Tyler'!B27 -> 0 | C27: ='Budget - Grantville'!C27+'Budget - Tyler'!C27 -> 0 | D27: ='Budget - Grantville'!D27+'Budget - Tyler'!D27 -> 0 | E27: ='Budget - Grantville'!E27+'Budget - Tyler'!E27 -> 0 | F27: ='Budget - Grantville'!F27+'Budget - Tyler'!F27 -> 0 | G27: ='Budget - Grantville'!G27+'Budget - Tyler'!G27 -> 0 | H27: ='Budget - Grantville'!H27+'Budget - Tyler'!H27 -> 0 | I27: ='Budget - Grantville'!I27+'Budget - Tyler'!I27 -> 0 | ... M27: ='Budget - Grantville'!M27+'Budget - Tyler'!M27 -> 0 | N27: =SUM(B27:M27) -> 0 | O27: =SUM(C27:N27) -> 0
A28: Other Income Sources | B28: ='Budget - Grantville'!B28+'Budget - Tyler'!B28 -> 0 | C28: ='Budget - Grantville'!C28+'Budget - Tyler'!C28 -> 0 | D28: ='Budget - Grantville'!D28+'Budget - Tyler'!D28 -> 0 | E28: ='Budget - Grantville'!E28+'Budget - Tyler'!E28 -> 0 | F28: ='Budget - Grantville'!F28+'Budget - Tyler'!F28 -> 0 | G28: ='Budget - Grantville'!G28+'Budget - Tyler'!G28 -> 0 | H28: ='Budget - Grantville'!H28+'Budget - Tyler'!H28 -> 0 | I28: ='Budget - Grantville'!I28+'Budget - Tyler'!I28 -> 0 | ... M28: ='Budget - Grantville'!M28+'Budget - Tyler'!M28 -> 0 | N28: =SUM(B28:M28) -> 0 | O28: =SUM(C28:N28) -> 0
A29: Other Income Sources | B29: ='Budget - Grantville'!B29+'Budget - Tyler'!B29 -> 0 | C29: ='Budget - Grantville'!C29+'Budget - Tyler'!C29 -> 0 | D29: ='Budget - Grantville'!D29+'Budget - Tyler'!D29 -> 0 | E29: ='Budget - Grantville'!E29+'Budget - Tyler'!E29 -> 0 | F29: ='Budget - Grantville'!F29+'Budget - Tyler'!F29 -> 0 | G29: ='Budget - Grantville'!G29+'Budget - Tyler'!G29 -> 0 | H29: ='Budget - Grantville'!H29+'Budget - Tyler'!H29 -> 0 | I29: ='Budget - Grantville'!I29+'Budget - Tyler'!I29 -> 0 | ... M29: ='Budget - Grantville'!M29+'Budget - Tyler'!M29 -> 0 | N29: =SUM(B29:M29) -> 0 | O29: =SUM(C29:N29) -> 0
A30: Total Ancillary Income | B30: =SUM(B24:B29) -> 816.55 | C30: =SUM(C24:C29) -> 810.6415 | D30: =SUM(D24:D29) -> 805.1466 | E30: =SUM(E24:E29) -> 809.13633 | F30: =SUM(F24:F29) -> 822.24679 | G30: =SUM(G24:G29) -> 834.43951 | H30: =SUM(H24:H29) -> 859.42875 | I30: =SUM(I24:I29) -> 882.66874 | ... M30: =SUM(M24:M29) -> 865.88176 | N30: =(((((((((((B30)+(C30))+(D30))+(E30))+(F30))+(G30))+(H30))+(I30))+(J30))+(K30))+(L30))+(M30) -> 10119.014 | O30: =SUM(O24:O29) -> 7232.79
A31: Total Revenue | B31: =B15+B22+B30 -> 26499.669 | C31: =C15+C22+C30 -> 26436.325 | D31: =D15+D22+D30 -> 26321.614 | E31: =E15+E22+E30 -> 26492.656 | F31: =F15+F22+F30 -> 26995.487 | G31: =G15+G22+G30 -> 27425.92 | H31: =H15+H22+H30 -> 28242.808 | I31: =I15+I22+I30 -> 28946.713 | ... M31: =M15+M22+M30 -> 28250.928 | N31: =SUM(B31:M31) -> 330870.59 | O31: =O15+O22+O30 -> 290012.98
A33: Expense Projection
A34: Advertising/Marketing
A35: PPC (payperclick) | B35: ='Budget - Grantville'!B35+'Budget - Tyler'!B35 -> 600 | C35: ='Budget - Grantville'!C35+'Budget - Tyler'!C35 -> 600 | D35: ='Budget - Grantville'!D35+'Budget - Tyler'!D35 -> 600 | E35: ='Budget - Grantville'!E35+'Budget - Tyler'!E35 -> 600 | F35: ='Budget - Grantville'!F35+'Budget - Tyler'!F35 -> 600 | G35: ='Budget - Grantville'!G35+'Budget - Tyler'!G35 -> 600 | H35: ='Budget - Grantville'!H35+'Budget - Tyler'!H35 -> 600 | I35: ='Budget - Grantville'!I35+'Budget - Tyler'!I35 -> 600 | ... M35: ='Budget - Grantville'!M35+'Budget - Tyler'!M35 -> 600 | N35: =(((((((((((B35)+(C35))+(D35))+(E35))+(F35))+(G35))+(H35))+(I35))+(J35))+(K35))+(L35))+(M35) -> 7200
A36: Print Materials | B36: ='Budget - Grantville'!B36+'Budget - Tyler'!B36 -> 0 | C36: ='Budget - Grantville'!C36+'Budget - Tyler'!C36 -> 0 | D36: ='Budget - Grantville'!D36+'Budget - Tyler'!D36 -> 200 | E36: ='Budget - Grantville'!E36+'Budget - Tyler'!E36 -> 0 | F36: ='Budget - Grantville'!F36+'Budget - Tyler'!F36 -> 0 | G36: ='Budget - Grantville'!G36+'Budget - Tyler'!G36 -> 0 | H36: ='Budget - Grantville'!H36+'Budget - Tyler'!H36 -> 200 | I36: ='Budget - Grantville'!I36+'Budget - Tyler'!I36 -> 0 | ... M36: ='Budget - Grantville'!M36+'Budget - Tyler'!M36 -> 0 | N36: =(((((((((((B36)+(C36))+(D36))+(E36))+(F36))+(G36))+(H36))+(I36))+(J36))+(K36))+(L36))+(M36) -> 600 | O36: 488.1
A37: Reputation & Social | B37: ='Budget - Grantville'!B37+'Budget - Tyler'!B37 -> 0 | C37: ='Budget - Grantville'!C37+'Budget - Tyler'!C37 -> 0 | D37: ='Budget - Grantville'!D37+'Budget - Tyler'!D37 -> 0 | E37: ='Budget - Grantville'!E37+'Budget - Tyler'!E37 -> 0 | F37: ='Budget - Grantville'!F37+'Budget - Tyler'!F37 -> 0 | G37: ='Budget - Grantville'!G37+'Budget - Tyler'!G37 -> 0 | H37: ='Budget - Grantville'!H37+'Budget - Tyler'!H37 -> 0 | I37: ='Budget - Grantville'!I37+'Budget - Tyler'!I37 -> 0 | ... M37: ='Budget - Grantville'!M37+'Budget - Tyler'!M37 -> 0 | N37: =(((((((((((B37)+(C37))+(D37))+(E37))+(F37))+(G37))+(H37))+(I37))+(J37))+(K37))+(L37))+(M37) -> 0
A38: Website | B38: ='Budget - Grantville'!B38+'Budget - Tyler'!B38 -> 600 | C38: ='Budget - Grantville'!C38+'Budget - Tyler'!C38 -> 600 | D38: ='Budget - Grantville'!D38+'Budget - Tyler'!D38 -> 600 | E38: ='Budget - Grantville'!E38+'Budget - Tyler'!E38 -> 600 | F38: ='Budget - Grantville'!F38+'Budget - Tyler'!F38 -> 600 | G38: ='Budget - Grantville'!G38+'Budget - Tyler'!G38 -> 600 | H38: ='Budget - Grantville'!H38+'Budget - Tyler'!H38 -> 600 | I38: ='Budget - Grantville'!I38+'Budget - Tyler'!I38 -> 600 | ... M38: ='Budget - Grantville'!M38+'Budget - Tyler'!M38 -> 600 | N38: =(((((((((((B38)+(C38))+(D38))+(E38))+(F38))+(G38))+(H38))+(I38))+(J38))+(K38))+(L38))+(M38) -> 7200 | O38: 6716
A39: Sparefoot | B39: ='Budget - Grantville'!B39+'Budget - Tyler'!B39 -> 0 | C39: ='Budget - Grantville'!C39+'Budget - Tyler'!C39 -> 0 | D39: ='Budget - Grantville'!D39+'Budget - Tyler'!D39 -> 0 | E39: ='Budget - Grantville'!E39+'Budget - Tyler'!E39 -> 0 | F39: ='Budget - Grantville'!F39+'Budget - Tyler'!F39 -> 0 | G39: ='Budget - Grantville'!G39+'Budget - Tyler'!G39 -> 0 | H39: ='Budget - Grantville'!H39+'Budget - Tyler'!H39 -> 0 | I39: ='Budget - Grantville'!I39+'Budget - Tyler'!I39 -> 0 | ... M39: ='Budget - Grantville'!M39+'Budget - Tyler'!M39 -> 0 | N39: =(((((((((((B39)+(C39))+(D39))+(E39))+(F39))+(G39))+(H39))+(I39))+(J39))+(K39))+(L39))+(M39) -> 0 | O39: 11409.35
A40: Advertising/Marketing | B40: =SUM(B35:B39) -> 1200 | C40: =SUM(C35:C39) -> 1200 | D40: =SUM(D35:D39) -> 1400 | E40: =SUM(E35:E39) -> 1200 | F40: =SUM(F35:F39) -> 1200 | G40: =SUM(G35:G39) -> 1200 | H40: =SUM(H35:H39) -> 1400 | I40: =SUM(I35:I39) -> 1200 | ... M40: =SUM(M35:M39) -> 1200 | N40: =(((((((((((B40)+(C40))+(D40))+(E40))+(F40))+(G40))+(H40))+(I40))+(J40))+(K40))+(L40))+(M40) -> 15000 | O40: =SUM(O35:O39) -> 18613.45
A41: Legal & Professional Fees | N41: =(((((((((((B41)+(C41))+(D41))+(E41))+(F41))+(G41))+(H41))+(I41))+(J41))+(K41))+(L41))+(M41) -> 0
A42: Auction Expenses | B42: ='Budget - Grantville'!B42+'Budget - Tyler'!B42 -> 200 | C42: ='Budget - Grantville'!C42+'Budget - Tyler'!C42 -> 200 | D42: ='Budget - Grantville'!D42+'Budget - Tyler'!D42 -> 200 | E42: ='Budget - Grantville'!E42+'Budget - Tyler'!E42 -> 200 | F42: ='Budget - Grantville'!F42+'Budget - Tyler'!F42 -> 200 | G42: ='Budget - Grantville'!G42+'Budget - Tyler'!G42 -> 200 | H42: ='Budget - Grantville'!H42+'Budget - Tyler'!H42 -> 200 | I42: ='Budget - Grantville'!I42+'Budget - Tyler'!I42 -> 200 | ... M42: ='Budget - Grantville'!M42+'Budget - Tyler'!M42 -> 200 | N42: =(((((((((((B42)+(C42))+(D42))+(E42))+(F42))+(G42))+(H42))+(I42))+(J42))+(K42))+(L42))+(M42) -> 2400 | O42: 2131.2
...

Sheet Budget - Tyler
B1: Topeka Self Storage - Tyler
B2: Budget
B3: January - December 2026
B5: 46023 | C5: 46054 | D5: 46082 | E5: 46113 | F5: 46143 | G5: 46174 | H5: 46204 | I5: 46235 | J5: 46266 | K5: 46296 | L5: 46327 | M5: 46357
A6: Rented | B6: 3 | C6: 3 | D6: 3 | E6: 5 | F6: 5 | G6: 5 | H6: 8 | I6: 8 | J6: 5 | K6: 5 | L6: 5 | M6: 5
A7: Vacated | B7: =B8*0.06 -> 4.26 | C7: =B8*0.07 -> 4.97 | D7: =C8*0.07 -> 4.8321 | E7: =D8*0.07 -> 4.703853 | F7: =E8*0.07 -> 4.7245833 | G7: =F8*0.07 -> 4.7438625 | H7: =G8*0.07 -> 4.7617921 | I7: =H8*0.07 -> 4.9884666 | J7: =I8*0.07 -> 5.199274 | ... M7: =L8*0.07 -> 5.1602874
A8: Net occupied | B8: 71 | C8: =B8+C6-C7 -> 69.03 | D8: =C8+D6-D7 -> 67.1979 | E8: =D8+E6-E7 -> 67.494047 | F8: =E8+F6-F7 -> 67.769464 | G8: =F8+G6-G7 -> 68.025601 | H8: =G8+H6-H7 -> 71.263809 | I8: =H8+I6-I7 -> 74.275343 | J8: =I8+J6-J7 -> 74.076069 | ... M8: =L8+M6-M7 -> 73.558104
A9: % occupied | B9: =B8/82 -> 0.86585366 | C9: =C8/82 -> 0.84182927 | D9: =D8/82 -> 0.81948659 | E9: =E8/82 -> 0.82309813 | F9: =F8/82 -> 0.82645687 | G9: =G8/82 -> 0.8295805 | H9: =H8/82 -> 0.86907084 | I9: =I8/82 -> 0.90579686 | ... M9: =M8/82 -> 0.89705005
B10: 46023 | C10: 46054 | D10: 46082 | E10: 46113 | F10: 46143 | G10: 46174 | H10: 46204 | I10: 46235 | J10: 46266 | K10: 46296 | L10: 46327 | M10: 46357 | N10: Total
A11: Revenue Projection
A12: Rent Income | B12: =(8334/73)*B8*0.97 -> 7862.5011 | C12: =(8334/73)*C8*0.97 -> 7644.3444 | D12: =(8334/73)*D8*0.97 -> 7441.4586 | E12: =(8334/73)*E8*0.97 -> 7474.2538 | F12: =(8334/73)*F8*0.97 -> 7504.7533 | G12: =(8334/73)*G8*0.97 -> 7533.1178 | H12: =(8334/73)*H8*0.97 -> 7891.7152 | I12: =(8334/73)*I8*0.97 -> 8225.2107 | ... M12: =(8334/73)*M8*0.97 -> 8145.7842 | N12: =SUM(B12:M12) -> 94272.437
A13: Other Rent Income | N13: =SUM(B13:M13) -> 0
A14: Other Rent Income | N14: =SUM(B14:M14) -> 0
A15: Total Rental Income | B15: =SUM(B12:B14) -> 7862.5011 | C15: =SUM(C12:C14) -> 7644.3444 | D15: =SUM(D12:D14) -> 7441.4586 | E15: =SUM(E12:E14) -> 7474.2538 | F15: =SUM(F12:F14) -> 7504.7533 | G15: =SUM(G12:G14) -> 7533.1178 | H15: =SUM(H12:H14) -> 7891.7152 | I15: =SUM(I12:I14) -> 8225.2107 | ... M15: =SUM(M12:M14) -> 8145.7842 | N15: =(((((((((((B15)+(C15))+(D15))+(E15))+(F15))+(G15))+(H15))+(I15))+(J15))+(K15))+(L15))+(M15) -> 94272.437
A16: Fee Income
A17: Admin Fees | B17: =B6*20 -> 60 | C17: =C6*20 -> 60 | D17: =D6*20 -> 60 | E17: =E6*20 -> 100 | F17: =F6*20 -> 100 | G17: =G6*20 -> 100 | H17: =H6*20 -> 160 | I17: =I6*20 -> 160 | ... M17: =M6*20 -> 100 | N17: =SUM(B17:M17) -> 1200
A18: Late Fee Income | B18: =B12*0.03 -> 235.87503 | C18: =C12*0.03 -> 229.33033 | D18: =D12*0.03 -> 223.24376 | E18: =E12*0.03 -> 224.22761 | F18: =F12*0.03 -> 225.1426 | G18: =G12*0.03 -> 225.99353 | H18: =H12*0.03 -> 236.75146 | I18: =I12*0.03 -> 246.75632 | ... M18: =M12*0.03 -> 244.37352 | N18: =SUM(B18:M18) -> 2828.1731
A19: Convenience Fee | B19: =5*(B8*0.05) -> 17.75 | C19: =5*(C8*0.05) -> 17.2575 | D19: =5*(D8*0.05) -> 16.799475 | E19: =5*(E8*0.05) -> 16.873512 | F19: =5*(F8*0.05) -> 16.942366 | G19: =5*(G8*0.05) -> 17.0064 | H19: =5*(H8*0.05) -> 17.815952 | I19: =5*(I8*0.05) -> 18.568836 | ... M19: =5*(M8*0.05) -> 18.389526 | N19: =SUM(B19:M19) -> 212.82487
A20: General Fee Income | N20: =SUM(B20:M20) -> 0
A21: Other Fee | N21: =SUM(B21:M21) -> 0
A22: Total Fee Income | B22: =SUM(B17:B21) -> 313.62503 | C22: =SUM(C17:C21) -> 306.58783 | D22: =SUM(D17:D21) -> 300.04323 | E22: =SUM(E17:E21) -> 341.10113 | F22: =SUM(F17:F21) -> 342.08496 | G22: =SUM(G17:G21) -> 342.99993 | H22: =SUM(H17:H21) -> 414.56741 | I22: =SUM(I17:I21) -> 425.32516 | ... M22: =SUM(M17:M21) -> 362.76305 | N22: =(((((((((((B22)+(C22))+(D22))+(E22))+(F22))+(G22))+(H22))+(I22))+(J22))+(K22))+(L22))+(M22) -> 4240.998
A23: Ancillary Income
A24: Merchandise Income | B24: 0 | C24: 0 | D24: 0 | E24: 0 | F24: 0 | G24: 0 | H24: 0 | I24: 0 | J24: 0 | K24: 0 | L24: 0 | M24: 0 | N24: =SUM(B24:M24) -> 0
A25: Tenant Protection | B25: =B8*0.91*5 -> 323.05 | C25: =C8*0.91*5 -> 314.0865 | D25: =D8*0.91*5 -> 305.75045 | E25: =E8*0.91*5 -> 307.09791 | F25: =F8*0.91*5 -> 308.35106 | G25: =G8*0.91*5 -> 309.51649 | H25: =H8*0.91*5 -> 324.25033 | I25: =I8*0.91*5 -> 337.95281 | ... M25: =M8*0.91*5 -> 334.68937 | N25: =SUM(B25:M25) -> 3873.4126
A26: Truck Rentals | N26: =SUM(B26:M26) -> 0
A27: Propane Sales | N27: =SUM(B27:M27) -> 0
A28: Other Income Sources | N28: =SUM(B28:M28) -> 0
A29: Other Income Sources | N29: =SUM(B29:M29) -> 0
A30: Total Ancillary Income | B30: =SUM(B24:B29) -> 323.05 | C30: =SUM(C24:C29) -> 314.0865 | D30: =SUM(D24:D29) -> 305.75045 | E30: =SUM(E24:E29) -> 307.09791 | F30: =SUM(F24:F29) -> 308.35106 | G30: =SUM(G24:G29) -> 309.51649 | H30: =SUM(H24:H29) -> 324.25033 | I30: =SUM(I24:I29) -> 337.95281 | ... M30: =SUM(M24:M29) -> 334.68937 | N30: =(((((((((((B30)+(C30))+(D30))+(E30))+(F30))+(G30))+(H30))+(I30))+(J30))+(K30))+(L30))+(M30) -> 3873.4126
A31: Total Revenue | B31: =B15+B22+B30 -> 8499.1761 | C31: =C15+C22+C30 -> 8265.0187 | D31: =D15+D22+D30 -> 8047.2523 | E31: =E15+E22+E30 -> 8122.4528 | F31: =F15+F22+F30 -> 8155.1893 | G31: =G15+G22+G30 -> 8185.6342 | H31: =H15+H22+H30 -> 8630.5329 | I31: =I15+I22+I30 -> 8988.4887 | ... M31: =M15+M22+M30 -> 8843.2366 | N31: =SUM(B31:M31) -> 102386.85
A33: Expense Projection
A34: Advertising/Marketing
A35: PPC (payperclick) | B35: 300 | C35: =B35 -> 300 | D35: =C35 -> 300 | E35: =D35 -> 300 | F35: =E35 -> 300 | G35: =F35 -> 300 | H35: =G35 -> 300 | I35: =H35 -> 300 | J35: =I35 -> 300 | ... M35: =L35 -> 300 | N35: =(((((((((((B35)+(C35))+(D35))+(E35))+(F35))+(G35))+(H35))+(I35))+(J35))+(K35))+(L35))+(M35) -> 3600
A36: Print Materials | B36: 0 | C36: 0 | D36: 100 | E36: 0 | F36: =0 -> 0 | G36: =0 -> 0 | H36: 100 | I36: =0 -> 0 | J36: =0 -> 0 | K36: =0 -> 0 | L36: 100 | M36: =0 -> 0 | N36: =(((((((((((B36)+(C36))+(D36))+(E36))+(F36))+(G36))+(H36))+(I36))+(J36))+(K36))+(L36))+(M36) -> 300
A37: Reputation & Social | B37: 0 | C37: =B37 -> 0 | D37: =C37 -> 0 | E37: =D37 -> 0 | F37: =E37 -> 0 | G37: =F37 -> 0 | H37: =G37 -> 0 | I37: =H37 -> 0 | J37: =I37 -> 0 | ... M37: =L37 -> 0 | N37: =(((((((((((B37)+(C37))+(D37))+(E37))+(F37))+(G37))+(H37))+(I37))+(J37))+(K37))+(L37))+(M37) -> 0
A38: Website | B38: 300 | C38: =B38 -> 300 | D38: =C38 -> 300 | E38: =D38 -> 300 | F38: =E38 -> 300 | G38: =F38 -> 300 | H38: =G38 -> 300 | I38: =H38 -> 300 | J38: =I38 -> 300 | ... M38: =L38 -> 300 | N38: =(((((((((((B38)+(C38))+(D38))+(E38))+(F38))+(G38))+(H38))+(I38))+(J38))+(K38))+(L38))+(M38) -> 3600
A39: Sparefoot | B39: 0 | C39: =B39 -> 0 | D39: =C39 -> 0 | E39: =D39 -> 0 | F39: =E39 -> 0 | G39: =F39 -> 0 | H39: =G39 -> 0 | I39: =H39 -> 0 | J39: =I39 -> 0 | ... M39: =L39 -> 0 | N39: =(((((((((((B39)+(C39))+(D39))+(E39))+(F39))+(G39))+(H39))+(I39))+(J39))+(K39))+(L39))+(M39) -> 0
A40: Advertising/Marketing | B40: =SUM(B35:B39) -> 600 | C40: =SUM(C35:C39) -> 600 | D40: =SUM(D35:D39) -> 700 | E40: =SUM(E35:E39) -> 600 | F40: =SUM(F35:F39) -> 600 | G40: =SUM(G35:G39) -> 600 | H40: =SUM(H35:H39) -> 700 | I40: =SUM(I35:I39) -> 600 | ... M40: =SUM(M35:M39) -> 600 | N40: =(((((((((((B40)+(C40))+(D40))+(E40))+(F40))+(G40))+(H40))+(I40))+(J40))+(K40))+(L40))+(M40) -> 7500
A41: Legal & Professional Fees | N41: =(((((((((((B41)+(C41))+(D41))+(E41))+(F41))+(G41))+(H41))+(I41))+(J41))+(K41))+(L41))+(M41) -> 0
A42: Auction Expenses | B42: 100 | C42: 100 | D42: 100 | E42: 100 | F42: 100 | G42: 100 | H42: 100 | I42: 100 | J42: 100 | K42: 100 | L42: 100 | M42: 100 | N42: =(((((((((((B42)+(C42))+(D42))+(E42))+(F42))+(G42))+(H42))+(I42))+(J42))+(K42))+(L42))+(M42) -> 1200
...

Sheet Budget - Grantville
B1: Topeka Self Storage - Grantville
B2: Budget
B3: January - December 2026
B5: 46023 | C5: 46054 | D5: 46082 | E5: 46113 | F5: 46143 | G5: 46174 | H5: 46204 | I5: 46235 | J5: 46266 | K5: 46296 | L5: 46327 | M5: 46357
A6: Rented | B6: 5 | C6: 8 | D6: 8 | E6: 8 | F6: 10 | G6: 10 | H6: 10 | I6: 10 | J6: 7 | K6: 7 | L6: 7 | M6: 7
A7: Vacated | B7: =B8*0.06 -> 6.3 | C7: =B8*0.07 -> 7.35 | D7: =C8*0.07 -> 7.3955 | E7: =D8*0.07 -> 7.437815 | F7: =E8*0.07 -> 7.477168 | G7: =F8*0.07 -> 7.6537662 | H7: =G8*0.07 -> 7.8180026 | I7: =H8*0.07 -> 7.9707424 | J7: =I8*0.07 -> 8.1127904 | ... L7: =K8*0.07 -> 7.9624524 | M7: =L8*0.06 -> 6.7672121
A8: Net occupied | B8: 105 | C8: =B8+C6-C7 -> 105.65 | D8: =C8+D6-D7 -> 106.2545 | E8: =D8+E6-E7 -> 106.81669 | F8: =E8+F6-F7 -> 109.33952 | G8: =F8+G6-G7 -> 111.68575 | H8: =G8+H6-H7 -> 113.86775 | I8: =H8+I6-I7 -> 115.89701 | J8: =I8+J6-J7 -> 114.78422 | ... M8: =L8+M6-M7 -> 113.01966
A9: % occupied | B9: =B8/126 -> 0.83333333 | C9: =C8/126 -> 0.83849206 | D9: =D8/126 -> 0.84328968 | E9: =E8/126 -> 0.84775147 | F9: =F8/126 -> 0.86777394 | G9: =G8/126 -> 0.88639485 | H9: =H8/126 -> 0.90371229 | I9: =I8/126 -> 0.91981751 | ... M9: =M8/126 -> 0.8969814
B10: 46023 | C10: 46054 | D10: 46082 | E10: 46113 | F10: 46143 | G10: 46174 | H10: 46204 | I10: 46235 | J10: 46266 | K10: 46296 | L10: 46327 | M10: 46357 | N10: Total
A11: Revenue Projection
A12: Rent Income | B12: =(16568/100)*B8*0.97 -> 16874.508 | C12: =(16568/100)*C8*0.97 -> 16978.969 | D12: =(16568/100)*D8*0.97 -> 17076.118 | E12: =(16568/100)*E8*0.97 -> 17166.467 | F12: =(16568/100)*F8*0.97 -> 17571.91 | G12: =(16568/100)*G8*0.97 -> 17948.972 | H12: =(16568/100)*H8*0.97 -> 18299.64 | I12: =(16568/100)*I8*0.97 -> 18625.761 | ... M12: =(16568/100)*M8*0.97 -> 18163.344 | N12: =SUM(B12:M12) -> 213559.16
A13: Other Rent Income | N13: =SUM(B13:M13) -> 0
A14: Other Rent Income | N14: =SUM(B14:M14) -> 0
A15: Total Rental Income | B15: =SUM(B12:B14) -> 16874.508 | C15: =SUM(C12:C14) -> 16978.969 | D15: =SUM(D12:D14) -> 17076.118 | E15: =SUM(E12:E14) -> 17166.467 | F15: =SUM(F12:F14) -> 17571.91 | G15: =SUM(G12:G14) -> 17948.972 | H15: =SUM(H12:H14) -> 18299.64 | I15: =SUM(I12:I14) -> 18625.761 | ... M15: =SUM(M12:M14) -> 18163.344 | N15: =(((((((((((B15)+(C15))+(D15))+(E15))+(F15))+(G15))+(H15))+(I15))+(J15))+(K15))+(L15))+(M15) -> 213559.16
A16: Fee Income
A17: Admin Fees | B17: =B6*20 -> 100 | C17: =C6*20 -> 160 | D17: =D6*20 -> 160 | E17: =E6*20 -> 160 | F17: =F6*20 -> 200 | G17: =G6*20 -> 200 | H17: =H6*20 -> 200 | I17: =I6*20 -> 200 | ... M17: =M6*20 -> 140 | N17: =SUM(B17:M17) -> 1940
A18: Late Fee Income | B18: =B12*0.03 -> 506.23524 | C18: =C12*0.03 -> 509.36908 | D18: =D12*0.03 -> 512.28355 | E18: =E12*0.03 -> 514.994 | F18: =F12*0.03 -> 527.1573 | G18: =G12*0.03 -> 538.46917 | H18: =H12*0.03 -> 548.98921 | I18: =I12*0.03 -> 558.77284 | ... M18: =M12*0.03 -> 544.90031 | N18: =SUM(B18:M18) -> 6406.7747
A19: Convenience Fee | B19: =5*(B8*0.05) -> 26.25 | C19: =5*(C8*0.05) -> 26.4125 | D19: =5*(D8*0.05) -> 26.563625 | E19: =5*(E8*0.05) -> 26.704171 | F19: =5*(F8*0.05) -> 27.334879 | G19: =5*(G8*0.05) -> 27.921438 | H19: =5*(H8*0.05) -> 28.466937 | I19: =5*(I8*0.05) -> 28.974251 | ... M19: =5*(M8*0.05) -> 28.254914 | N19: =SUM(B19:M19) -> 332.21282
A20: General Fee Income | N20: =SUM(B20:M20) -> 0
A21: Other Fee | N21: =SUM(B21:M21) -> 0
A22: Total Fee Income | B22: =SUM(B17:B21) -> 632.48524 | C22: =SUM(C17:C21) -> 695.78158 | D22: =SUM(D17:D21) -> 698.84717 | E22: =SUM(E17:E21) -> 701.69817 | F22: =SUM(F17:F21) -> 754.49218 | G22: =SUM(G17:G21) -> 766.39061 | H22: =SUM(H17:H21) -> 777.45615 | I22: =SUM(I17:I21) -> 787.7471 | ... M22: =SUM(M17:M21) -> 713.15522 | N22: =(((((((((((B22)+(C22))+(D22))+(E22))+(F22))+(G22))+(H22))+(I22))+(J22))+(K22))+(L22))+(M22) -> 8678.9875
A23: Ancillary Income
A24: Merchandise Income | B24: 0 | C24: 0 | D24: 0 | E24: 0 | F24: 0 | G24: 0 | H24: 0 | I24: 0 | J24: 0 | K24: 0 | L24: 0 | M24: 0 | N24: =SUM(B24:M24) -> 0
A25: Tenant Protection | B25: =B8*0.94*5 -> 493.5 | C25: =C8*0.94*5 -> 496.555 | D25: =D8*0.94*5 -> 499.39615 | E25: =E8*0.94*5 -> 502.03842 | F25: =F8*0.94*5 -> 513.89573 | G25: =G8*0.94*5 -> 524.92303 | H25: =H8*0.94*5 -> 535.17842 | I25: =I8*0.94*5 -> 544.71593 | ... M25: =M8*0.94*5 -> 531.19238 | N25: =SUM(B25:M25) -> 6245.601
A26: Truck Rentals | N26: =SUM(B26:M26) -> 0
A27: Propane Sales | N27: =SUM(B27:M27) -> 0
A28: Other Income Sources | N28: =SUM(B28:M28) -> 0
A29: Other Income Sources | N29: =SUM(B29:M29) -> 0
A30: Total Ancillary Income | B30: =SUM(B24:B29) -> 493.5 | C30: =SUM(C24:C29) -> 496.555 | D30: =SUM(D24:D29) -> 499.39615 | E30: =SUM(E24:E29) -> 502.03842 | F30: =SUM(F24:F29) -> 513.89573 | G30: =SUM(G24:G29) -> 524.92303 | H30: =SUM(H24:H29) -> 535.17842 | I30: =SUM(I24:I29) -> 544.71593 | ... M30: =SUM(M24:M29) -> 531.19238 | N30: =(((((((((((B30)+(C30))+(D30))+(E30))+(F30))+(G30))+(H30))+(I30))+(J30))+(K30))+(L30))+(M30) -> 6245.601
A31: Total Revenue | B31: =B15+B22+B30 -> 18000.493 | C31: =C15+C22+C30 -> 18171.306 | D31: =D15+D22+D30 -> 18274.362 | E31: =E15+E22+E30 -> 18370.203 | F31: =F15+F22+F30 -> 18840.298 | G31: =G15+G22+G30 -> 19240.286 | H31: =H15+H22+H30 -> 19612.275 | I31: =I15+I22+I30 -> 19958.224 | ... M31: =M15+M22+M30 -> 19407.691 | N31: =SUM(B31:M31) -> 228483.74
A33: Expense Projection
A34: Advertising/Marketing
A35: PPC (payperclick) | B35: 300 | C35: =B35 -> 300 | D35: =C35 -> 300 | E35: =D35 -> 300 | F35: =E35 -> 300 | G35: =F35 -> 300 | H35: =G35 -> 300 | I35: =H35 -> 300 | J35: =I35 -> 300 | ... M35: =L35 -> 300 | N35: =(((((((((((B35)+(C35))+(D35))+(E35))+(F35))+(G35))+(H35))+(I35))+(J35))+(K35))+(L35))+(M35) -> 3600
A36: Print Materials | B36: 0 | C36: 0 | D36: 100 | E36: 0 | F36: =0 -> 0 | G36: =0 -> 0 | H36: 100 | I36: =0 -> 0 | J36: =0 -> 0 | K36: =0 -> 0 | L36: 100 | M36: =0 -> 0 | N36: =(((((((((((B36)+(C36))+(D36))+(E36))+(F36))+(G36))+(H36))+(I36))+(J36))+(K36))+(L36))+(M36) -> 300
A37: Reputation & Social | B37: 0 | C37: =B37 -> 0 | D37: =C37 -> 0 | E37: =D37 -> 0 | F37: =E37 -> 0 | G37: =F37 -> 0 | H37: =G37 -> 0 | I37: =H37 -> 0 | J37: =I37 -> 0 | ... M37: =L37 -> 0 | N37: =(((((((((((B37)+(C37))+(D37))+(E37))+(F37))+(G37))+(H37))+(I37))+(J37))+(K37))+(L37))+(M37) -> 0
A38: Website | B38: 300 | C38: =B38 -> 300 | D38: =C38 -> 300 | E38: =D38 -> 300 | F38: =E38 -> 300 | G38: =F38 -> 300 | H38: =G38 -> 300 | I38: =H38 -> 300 | J38: =I38 -> 300 | ... M38: =L38 -> 300 | N38: =(((((((((((B38)+(C38))+(D38))+(E38))+(F38))+(G38))+(H38))+(I38))+(J38))+(K38))+(L38))+(M38) -> 3600
A39: Sparefoot | B39: 0 | C39: =B39 -> 0 | D39: =C39 -> 0 | E39: =D39 -> 0 | F39: =E39 -> 0 | G39: =F39 -> 0 | H39: =G39 -> 0 | I39: =H39 -> 0 | J39: =I39 -> 0 | ... M39: =L39 -> 0 | N39: =(((((((((((B39)+(C39))+(D39))+(E39))+(F39))+(G39))+(H39))+(I39))+(J39))+(K39))+(L39))+(M39) -> 0
A40: Advertising/Marketing | B40: =SUM(B35:B39) -> 600 | C40: =SUM(C35:C39) -> 600 | D40: =SUM(D35:D39) -> 700 | E40: =SUM(E35:E39) -> 600 | F40: =SUM(F35:F39) -> 600 | G40: =SUM(G35:G39) -> 600 | H40: =SUM(H35:H39) -> 700 | I40: =SUM(I35:I39) -> 600 | ... M40: =SUM(M35:M39) -> 600 | N40: =(((((((((((B40)+(C40))+(D40))+(E40))+(F40))+(G40))+(H40))+(I40))+(J40))+(K40))+(L40))+(M40) -> 7500
A41: Legal & Professional Fees | N41: =(((((((((((B41)+(C41))+(D41))+(E41))+(F41))+(G41))+(H41))+(I41))+(J41))+(K41))+(L41))+(M41) -> 0
A42: Auction Expenses | B42: 100 | C42: 100 | D42: 100 | E42: 100 | F42: 100 | G42: 100 | H42: 100 | I42: 100 | J42: 100 | K42: 100 | L42: 100 | M42: 100 | N42: =(((((((((((B42)+(C42))+(D42))+(E42))+(F42))+(G42))+(H42))+(I42))+(J42))+(K42))+(L42))+(M42) -> 1200
...
